<?xml version="1.0" encoding="utf-8"?>
<testsuites>
    <testsuite name="pytest" errors="0" failures="0" skipped="1" tests="42" time="3.525"
        timestamp="2024-08-22T22:27:25.541115" hostname="DESKTOP-WEWEWEWE">
        <testcase classname="test.random.Service"
            name="test_adds" time="0.002">
        </testcase>
        <testcase
            classname="test.random.Service2"
            name="test_adds2" time="0.664" />
    </testsuite>
    <testsuite name="pytest2" errors="0" failures="0" skipped="1" tests="42" time="3.525"
        timestamp="2024-08-22T22:27:25.541115" hostname="DESKTOP-WEWEWEWE">
        <testcase classname="test.random.Service3"
            name="test_adds3" time="0.002">
        </testcase>
        <testcase
            classname="test.random.Service4"
            name="test_adds4" time="0.664" />
        <testcase classname="test.utils.test_utils" name="test_failing_test" time="0.006">
            <failure message="assert 1 == 2">def test_failing_test():
                """Used to test we are failing"""
                &gt; assert 1 == 2
                E assert 1 == 2

                test\utils\test_utils.py:65: AssertionError</failure>
        </testcase>
        <testcase classname="test.random.ServiceNew"
            name="test_adds" time="0.002">
        </testcase>
    </testsuite>
</testsuites>